Workbook

Sheet Difference
A1: Condition Document No | B1: Condition Text | C1: Product | D1: Product Text | E1: Incentive | F1: AS-IS Qty | G1: AS-IS Amt($) | H1: Difference | I1: Total Amount
A2: A0S3A0A250000641 | B2: VITEL W24-W26 ECO ST Promo | C2: G-WATCH-ULTRA | D2: G-WATCH-ULTRA | E2: 30 | F2: 161 | G2: 4830 | H2: =('Sent To Samsung'!J2-Invoiced!J2) -> 46 | I2: =H2*E2 -> 1380
A3: A0S3A0A250000641 | B3: VITEL W24-W26 ECO ST Promo | C3: SM-X520NLBATPA | D3: TABLET,SM-X520,LIGHT BLUE,TPA | E3: 30 | F3: 385 | G3: 11550 | H3: =('Sent To Samsung'!J3-Invoiced!J3) -> 231 | I3: =H3*E3 -> 6930
A4: A0S3A0A250000641 | B4: VITEL W24-W26 ECO ST Promo | C4: SM-X520NLBETPA | D4: TABLET,SM-X520,LIGHT BLUE,TPA | E4: 30 | F4: 3 | G4: 90 | H4: =('Sent To Samsung'!J4-Invoiced!J4) -> 3 | I4: =H4*E4 -> 90
A5: A0S3A0A250000641 | B5: VITEL W24-W26 ECO ST Promo | C5: SM-X520NZAATPA | D5: TABLET,SM-X520,GRAY,TPA | E5: 30 | F5: 348 | G5: 10440 | H5: =('Sent To Samsung'!J5-Invoiced!J5) -> 105 | I5: =H5*E5 -> 3150
A6: A0S3A0A250000641 | B6: VITEL W24-W26 ECO ST Promo | C6: SM-X520NZAETPA | D6: TABLET,SM-X520,GRAY,TPA | E6: 30 | F6: 3 | G6: 90 | H6: =('Sent To Samsung'!J6-Invoiced!J6) -> 3 | I6: =H6*E6 -> 90
A7: A0S3A0A250000641 | B7: VITEL W24-W26 ECO ST Promo | C7: SM-X520NZSATPA | D7: TABLET,SM-X520,SILVER,TPA | E7: 30 | F7: 347 | G7: 10410 | H7: =('Sent To Samsung'!J7-Invoiced!J7) -> 230 | I7: =H7*E7 -> 6900
A8: A0S3A0A250000641 | B8: VITEL W24-W26 ECO ST Promo | C8: SM-X520NZSETPA | D8: TABLET,SM-X520,SILVER,TPA | E8: 30 | F8: 3 | G8: 90 | H8: =('Sent To Samsung'!J8-Invoiced!J8) -> 3 | I8: =H8*E8 -> 90
A9: A0S3A0A250000641 | B9: VITEL W24-W26 ECO ST Promo | C9: SM-X526BLBATPA | D9: TABLET,SM-X526B,LIGHT BLUE,TPA | E9: 30 | F9: 135 | G9: 4050 | H9: =('Sent To Samsung'!J9-Invoiced!J9) -> 110 | I9: =H9*E9 -> 3300
A10: A0S3A0A250000641 | B10: VITEL W24-W26 ECO ST Promo | C10: SM-X526BZAATPA | D10: TABLET,SM-X526B,GRAY,TPA | E10: 30 | F10: 128 | G10: 3840 | H10: =('Sent To Samsung'!J10-Invoiced!J10) -> 97 | I10: =H10*E10 -> 2910
A11: A0S3A0A250000641 | B11: VITEL W24-W26 ECO ST Promo | C11: SM-X526BZSATPA | D11: TABLET,SM-X526B,SILVER,TPA | E11: 30 | F11: 174 | G11: 5220 | H11: =('Sent To Samsung'!J11-Invoiced!J11) -> 158 | I11: =H11*E11 -> 4740
A12: A0S3A0A250000641 | B12: VITEL W24-W26 ECO ST Promo | C12: SM-X620NLBATPA | D12: TABLET,SM-X620,LIGHT BLUE,TPA | E12: 30 | F12: 162 | G12: 4860 | H12: =('Sent To Samsung'!J12-Invoiced!J12) -> 145 | I12: =H12*E12 -> 4350
A13: A0S3A0A250000641 | B13: VITEL W24-W26 ECO ST Promo | C13: SM-X620NLBETPA | D13: TABLET,SM-X620,LIGHT BLUE,TPA | E13: 30 | F13: 3 | G13: 90 | H13: =('Sent To Samsung'!J13-Invoiced!J13) -> 3 | I13: =H13*E13 -> 90
... A51: A0S3A0A250000682 | B51: VITEL W26 MX Sell-Thru Promotion | C51: SM-M556BZKMTPA | D51: MOBILE,SM-M556B/DS,BLACK,TPA | E51: 7 | F51: 44 | G51: 308 | H51: =('Sent To Samsung'!J51-Invoiced!J51) -> 0 | I51: =H51*E51 -> 0

Sheet Invoiced
A1: Condition Document No | B1: Condition Text | C1: Group Condition Document No | D1: Customer Text | E1: Product | F1: Product Text | G1: Incentive | H1: AS-IS Qty | I1: AS-IS Amt($) | J1: TO-BE Qty | K1: TO-BE Amt($) | L1: DELTA Qty | M1: DELTA Amt($) | N1: Start Date of Condition | O1: End Date of Condition
A2: A0S3A0A250000641 | B2: VITEL W24-W26 ECO ST Promo | C2: A2S3A0A250000225 | D2: VITEL MOBILE, INC. | E2: G-WATCH-ULTRA | F2: G-WATCH-ULTRA | G2: 30 | H2: 161 | I2: 4830 | J2: 114 | K2: =J2*G2 -> 3420 | L2: =J2-H2 -> -47 | M2: =K2-I2 -> -1410 | N2: 45817 | O2: 45837
A3: A0S3A0A250000641 | B3: VITEL W24-W26 ECO ST Promo | C3: A2S3A0A250000225 | D3: VITEL MOBILE, INC. | E3: SM-X520NLBATPA | F3: TABLET,SM-X520,LIGHT BLUE,TPA | G3: 30 | H3: 385 | I3: 11550 | J3: 153 | K3: =J3*G3 -> 4590 | L3: =J3-H3 -> -232 | M3: =K3-I3 -> -6960 | N3: 45817 | O3: 45837
A4: A0S3A0A250000641 | B4: VITEL W24-W26 ECO ST Promo | C4: A2S3A0A250000225 | D4: VITEL MOBILE, INC. | E4: SM-X520NLBETPA | F4: TABLET,SM-X520,LIGHT BLUE,TPA | G4: 30 | H4: 3 | I4: 90 | J4: 0 | K4: =J4*G4 -> 0 | L4: =J4-H4 -> -3 | M4: =K4-I4 -> -90 | N4: 45817 | O4: 45837
A5: A0S3A0A250000641 | B5: VITEL W24-W26 ECO ST Promo | C5: A2S3A0A250000225 | D5: VITEL MOBILE, INC. | E5: SM-X520NZAATPA | F5: TABLET,SM-X520,GRAY,TPA | G5: 30 | H5: 348 | I5: 10440 | J5: 240 | K5: =J5*G5 -> 7200 | L5: =J5-H5 -> -108 | M5: =K5-I5 -> -3240 | N5: 45817 | O5: 45837
A6: A0S3A0A250000641 | B6: VITEL W24-W26 ECO ST Promo | C6: A2S3A0A250000225 | D6: VITEL MOBILE, INC. | E6: SM-X520NZAETPA | F6: TABLET,SM-X520,GRAY,TPA | G6: 30 | H6: 3 | I6: 90 | J6: 0 | K6: =J6*G6 -> 0 | L6: =J6-H6 -> -3 | M6: =K6-I6 -> -90 | N6: 45817 | O6: 45837
A7: A0S3A0A250000641 | B7: VITEL W24-W26 ECO ST Promo | C7: A2S3A0A250000225 | D7: VITEL MOBILE, INC. | E7: SM-X520NZSATPA | F7: TABLET,SM-X520,SILVER,TPA | G7: 30 | H7: 347 | I7: 10410 | J7: 115 | K7: =J7*G7 -> 3450 | L7: =J7-H7 -> -232 | M7: =K7-I7 -> -6960 | N7: 45817 | O7: 45837
A8: A0S3A0A250000641 | B8: VITEL W24-W26 ECO ST Promo | C8: A2S3A0A250000225 | D8: VITEL MOBILE, INC. | E8: SM-X520NZSETPA | F8: TABLET,SM-X520,SILVER,TPA | G8: 30 | H8: 3 | I8: 90 | J8: 0 | K8: =J8*G8 -> 0 | L8: =J8-H8 -> -3 | M8: =K8-I8 -> -90 | N8: 45817 | O8: 45837
A9: A0S3A0A250000641 | B9: VITEL W24-W26 ECO ST Promo | C9: A2S3A0A250000225 | D9: VITEL MOBILE, INC. | E9: SM-X526BLBATPA | F9: TABLET,SM-X526B,LIGHT BLUE,TPA | G9: 30 | H9: 135 | I9: 4050 | J9: 25 | K9: =J9*G9 -> 750 | L9: =J9-H9 -> -110 | M9: =K9-I9 -> -3300 | N9: 45817 | O9: 45837
A10: A0S3A0A250000641 | B10: VITEL W24-W26 ECO ST Promo | C10: A2S3A0A250000225 | D10: VITEL MOBILE, INC. | E10: SM-X526BZAATPA | F10: TABLET,SM-X526B,GRAY,TPA | G10: 30 | H10: 128 | I10: 3840 | J10: 31 | K10: =J10*G10 -> 930 | L10: =J10-H10 -> -97 | M10: =K10-I10 -> -2910 | N10: 45817 | O10: 45837
A11: A0S3A0A250000641 | B11: VITEL W24-W26 ECO ST Promo | C11: A2S3A0A250000225 | D11: VITEL MOBILE, INC. | E11: SM-X526BZSATPA | F11: TABLET,SM-X526B,SILVER,TPA | G11: 30 | H11: 174 | I11: 5220 | J11: 15 | K11: =J11*G11 -> 450 | L11: =J11-H11 -> -159 | M11: =K11-I11 -> -4770 | N11: 45817 | O11: 45837
A12: A0S3A0A250000641 | B12: VITEL W24-W26 ECO ST Promo | C12: A2S3A0A250000225 | D12: VITEL MOBILE, INC. | E12: SM-X620NLBATPA | F12: TABLET,SM-X620,LIGHT BLUE,TPA | G12: 30 | H12: 162 | I12: 4860 | J12: 15 | K12: =J12*G12 -> 450 | L12: =J12-H12 -> -147 | M12: =K12-I12 -> -4410 | N12: 45817 | O12: 45837
A13: A0S3A0A250000641 | B13: VITEL W24-W26 ECO ST Promo | C13: A2S3A0A250000225 | D13: VITEL MOBILE, INC. | E13: SM-X620NLBETPA | F13: TABLET,SM-X620,LIGHT BLUE,TPA | G13: 30 | H13: 3 | I13: 90 | J13: 0 | K13: =J13*G13 -> 0 | L13: =J13-H13 -> -3 | M13: =K13-I13 -> -90 | N13: 45817 | O13: 45837
... A24: A0S3A0A250000649 | B24: VITEL W24-W26 A9 Series Promotion | C24: A2S3A0A250000227 | D24: VITEL MOBILE, INC. | E24: G-TAB-A9+ | F24: G-TAB-A9+ | G24: 15 | H24: 5 | I24: 75 | J24: 430 | K24: =J24*G24 -> 6450 | L24: =J24-H24 -> 425 | M24: =K24-I24 -> 6375 | N24: 45817 | O24: 45837
A25: A0S3A0A250000679 | B25: VITEL W26 NRM Sell-Thru Promotion | C25: A2S3A0A250000241 | D25: VITEL MOBILE, INC. | E25: G-A16 | F25: G-A16 | G25: 10 | H25: 1120 | I25: 11200 | J25: 3979 | K25: =J25*G25 -> 39790 | L25: =J25-H25 -> 2859 | M25: =K25-I25 -> 28590 | N25: 45831 | O25: 45837 | P25: 486
A26: A0S3A0A250000679 | B26: VITEL W26 NRM Sell-Thru Promotion | C26: A2S3A0A250000241 | D26: VITEL MOBILE, INC. | E26: G-A16-5G | F26: G-A16-5G | G26: 5 | H26: 280 | I26: 1400 | J26: 28 | K26: =J26*G26 -> 140 | L26: =J26-H26 -> -252 | M26: =K26-I26 -> -1260 | N26: 45831 | O26: 45837 | P26: 28
A27: A0S3A0A250000679 | B27: VITEL W26 NRM Sell-Thru Promotion | C27: A2S3A0A250000241 | D27: VITEL MOBILE, INC. | E27: G-A26-5G | F27: G-A26-5G | G27: 20 | H27: 630 | I27: 12600 | J27: 219 | K27: =J27*G27 -> 4380 | L27: =J27-H27 -> -411 | M27: =K27-I27 -> -8220 | N27: 45831 | O27: 45837 | P27: 89
A28: A0S3A0A250000679 | B28: VITEL W26 NRM Sell-Thru Promotion | C28: A2S3A0A250000241 | D28: VITEL MOBILE, INC. | E28: G-A36-5G | F28: G-A36-5G | G28: 10 | H28: 420 | I28: 4200 | J28: 240 | K28: =J28*G28 -> 2400 | L28: =J28-H28 -> -180 | M28: =K28-I28 -> -1800 | N28: 45831 | O28: 45837 | P28: 70
A29: A0S3A0A250000679 | B29: VITEL W26 NRM Sell-Thru Promotion | C29: A2S3A0A250000241 | D29: VITEL MOBILE, INC. | E29: G-A56-5G | F29: G-A56-5G | G29: 10 | H29: 700 | I29: 7000 | J29: 706 | K29: =J29*G29 -> 7060 | L29: =J29-H29 -> 6 | M29: =K29-I29 -> 60 | N29: 45831 | O29: 45837 | P29: 311
A30: A0S3A0A250000679 | B30: VITEL W26 NRM Sell-Thru Promotion | C30: A2S3A0A250000241 | D30: VITEL MOBILE, INC. | E30: G-S24 | F30: G-S24 | G30: 10 | H30: 7 | I30: 70 | J30: 0 | K30: =J30*G30 -> 0 | L30: =J30-H30 -> -7 | M30: =K30-I30 -> -70 | N30: 45831 | O30: 45837
A31: A0S3A0A250000679 | B31: VITEL W26 NRM Sell-Thru Promotion | C31: A2S3A0A250000241 | D31: VITEL MOBILE, INC. | E31: G-S24+ | F31: G-S24+ | G31: 10 | H31: 7 | I31: 70 | J31: 0 | K31: =J31*G31 -> 0 | L31: =J31-H31 -> -7 | M31: =K31-I31 -> -70 | N31: 45831 | O31: 45837 | P31: 27
A32: A0S3A0A250000679 | B32: VITEL W26 NRM Sell-Thru Promotion | C32: A2S3A0A250000241 | D32: VITEL MOBILE, INC. | E32: G-S24-ULTRA | F32: G-S24-ULTRA | G32: 30 | H32: 105 | I32: 3150 | J32: 40 | K32: =J32*G32 -> 1200 | L32: =J32-H32 -> -65 | M32: =K32-I32 -> -1950 | N32: 45831 | O32: 45837 | P32: 156
A33: A0S3A0A250000679 | B33: VITEL W26 NRM Sell-Thru Promotion | C33: A2S3A0A250000241 | D33: VITEL MOBILE, INC. | E33: G-S25 | F33: G-S25 | G33: 30 | H33: 42 | I33: 1260 | J33: 0 | K33: =J33*G33 -> 0 | L33: =J33-H33 -> -42 | M33: =K33-I33 -> -1260 | N33: 45831 | O33: 45837
A34: A0S3A0A250000679 | B34: VITEL W26 NRM Sell-Thru Promotion | C34: A2S3A0A250000241 | D34: VITEL MOBILE, INC. | E34: G-S25+ | F34: G-S25+ | G34: 30 | H34: 42 | I34: 1260 | J34: 444 | K34: =J34*G34 -> 13320 | L34: =J34-H34 -> 402 | M34: =K34-I34 -> 12060 | N34: 45831 | O34: 45837
A35: A0S3A0A250000679 | B35: VITEL W26 NRM Sell-Thru Promotion | C35: A2S3A0A250000241 | D35: VITEL MOBILE, INC. | E35: G-S25-ULTRA | F35: G-S25-ULTRA | G35: 30 | H35: 140 | I35: 4200 | J35: 282 | K35: =J35*G35 -> 8460 | L35: =J35-H35 -> 142 | M35: =K35-I35 -> 4260 | N35: 45831 | O35: 45837
A36: A0S3A0A250000679 | B36: VITEL W26 NRM Sell-Thru Promotion | C36: A2S3A0A250000241 | D36: VITEL MOBILE, INC. | E36: SM-M556BLGMTPA | F36: MOBILE,SM-M556B/DS,LIGHT GREEN,TPA | G36: 7 | H36: 4 | I36: 28 | J36: 0 | K36: =J36*G36 -> 0 | L36: =J36-H36 -> -4 | M36: =K36-I36 -> -28 | N36: 45831 | O36: 45837
A37: A0S3A0A250000679 | B37: VITEL W26 NRM Sell-Thru Promotion | C37: A2S3A0A250000241 | D37: VITEL MOBILE, INC. | E37: SM-M556BZKMTPA | F37: MOBILE,SM-M556B/DS,BLACK,TPA | G37: 7 | H37: 4 | I37: 28 | J37: 0 | K37: =J37*G37 -> 0 | L37: =J37-H37 -> -4 | M37: =K37-I37 -> -28 | N37: 45831 | O37: 45837
A38: A0S3A0A250000682 | B38: VITEL W26 MX Sell-Thru Promotion | C38: A2S3A0A250000242 | D38: VITEL MOBILE, INC. | E38: G-A06 | F38: G-A06 | G38: 10 | H38: 744 | I38: 7440 | J38: 5640 | K38: =J38*G38 -> 56400 | L38: =J38-H38 -> 4896 | M38: =K38-I38 -> 48960 | N38: 45831 | O38: 45837 | P38: 5640
A39: A0S3A0A250000682 | B39: VITEL W26 MX Sell-Thru Promotion | C39: A2S3A0A250000242 | D39: VITEL MOBILE, INC. | E39: G-A16 | F39: G-A16 | G39: 10 | H39: 462 | I39: 4620 | J39: 1477 | K39: =J39*G39 -> 14770 | L39: =J39-H39 -> 1015 | M39: =K39-I39 -> 10150 | N39: 45831 | O39: 45837
A40: A0S3A0A250000682 | B40: VITEL W26 MX Sell-Thru Promotion | C40: A2S3A0A250000242 | D40: VITEL MOBILE, INC. | E40: G-A16-5G | F40: G-A16-5G | G40: 5 | H40: 111 | I40: 555 | J40: 145 | K40: =J40*G40 -> 725 | L40: =J40-H40 -> 34 | M40: =K40-I40 -> 170 | N40: 45831 | O40: 45837
A41: A0S3A0A250000682 | B41: VITEL W26 MX Sell-Thru Promotion | C41: A2S3A0A250000242 | D41: VITEL MOBILE, INC. | E41: G-A26-5G | F41: G-A26-5G | G41: 20 | H41: 147 | I41: 2940 | J41: 0 | K41: =J41*G41 -> 0 | L41: =J41-H41 -> -147 | M41: =K41-I41 -> -2940 | N41: 45831 | O41: 45837
A42: A0S3A0A250000682 | B42: VITEL W26 MX Sell-Thru Promotion | C42: A2S3A0A250000242 | D42: VITEL MOBILE, INC. | E42: G-A36-5G | F42: G-A36-5G | G42: 10 | H42: 247 | I42: 2470 | J42: 0 | K42: =J42*G42 -> 0 | L42: =J42-H42 -> -247 | M42: =K42-I42 -> -2470 | N42: 45831 | O42: 45837
A43: A0S3A0A250000682 | B43: VITEL W26 MX Sell-Thru Promotion | C43: A2S3A0A250000242 | D43: VITEL MOBILE, INC. | E43: G-A56-5G | F43: G-A56-5G | G43: 10 | H43: 211 | I43: 2110 | J43: 0 | K43: =J43*G43 -> 0 | L43: =J43-H43 -> -211 | M43: =K43-I43 -> -2110 | N43: 45831 | O43: 45837
A44: A0S3A0A250000682 | B44: VITEL W26 MX Sell-Thru Promotion | C44: A2S3A0A250000242 | D44: VITEL MOBILE, INC. | E44: G-S24 | F44: G-S24 | G44: 10 | H44: 19 | I44: 190 | J44: 0 | K44: =J44*G44 -> 0 | L44: =J44-H44 -> -19 | M44: =K44-I44 -> -190 | N44: 45831 | O44: 45837
A45: A0S3A0A250000682 | B45: VITEL W26 MX Sell-Thru Promotion | C45: A2S3A0A250000242 | D45: VITEL MOBILE, INC. | E45: G-S24+ | F45: G-S24+ | G45: 10 | H45: 63 | I45: 630 | J45: 0 | K45: =J45*G45 -> 0 | L45: =J45-H45 -> -63 | M45: =K45-I45 -> -630 | N45: 45831 | O45: 45837
A46: A0S3A0A250000682 | B46: VITEL W26 MX Sell-Thru Promotion | C46: A2S3A0A250000242 | D46: VITEL MOBILE, INC. | E46: G-S24-ULTRA | F46: G-S24-ULTRA | G46: 30 | H46: 102 | I46: 3060 | J46: 150 | K46: =J46*G46 -> 4500 | L46: =J46-H46 -> 48 | M46: =K46-I46 -> 1440 | N46: 45831 | O46: 45837
A47: A0S3A0A250000682 | B47: VITEL W26 MX Sell-Thru Promotion | C47: A2S3A0A250000242 | D47: VITEL MOBILE, INC. | E47: G-S25 | F47: G-S25 | G47: 30 | H47: 43 | I47: 1290 | J47: 20 | K47: =J47*G47 -> 600 | L47: =J47-H47 -> -23 | M47: =K47-I47 -> -690 | N47: 45831 | O47: 45837 | P47: 20
A48: A0S3A0A250000682 | B48: VITEL W26 MX Sell-Thru Promotion | C48: A2S3A0A250000242 | D48: VITEL MOBILE, INC. | E48: G-S25+ | F48: G-S25+ | G48: 30 | H48: 38 | I48: 1140 | J48: 125 | K48: =J48*G48 -> 3750 | L48: =J48-H48 -> 87 | M48: =K48-I48 -> 2610 | N48: 45831 | O48: 45837 | P48: 25
A49: A0S3A0A250000682 | B49: VITEL W26 MX Sell-Thru Promotion | C49: A2S3A0A250000242 | D49: VITEL MOBILE, INC. | E49: G-S25-ULTRA | F49: G-S25-ULTRA | G49: 30 | H49: 168 | I49: 5040 | J49: 798 | K49: =J49*G49 -> 23940 | L49: =J49-H49 -> 630 | M49: =K49-I49 -> 18900 | N49: 45831 | O49: 45837 | P49: 251
A50: A0S3A0A250000682 | B50: VITEL W26 MX Sell-Thru Promotion | C50: A2S3A0A250000242 | D50: VITEL MOBILE, INC. | E50: SM-M556BLGMTPA | F50: MOBILE,SM-M556B/DS,LIGHT GREEN,TPA | G50: 7 | H50: 44 | I50: 308 | J50: 0 | K50: =J50*G50 -> 0 | L50: =J50-H50 -> -44 | M50: =K50-I50 -> -308 | N50: 45831 | O50: 45837
...

Sheet Sent To Samsung
A1: Condition Document No | B1: Condition Text | C1: Group Condition Document No | D1: Customer Text | E1: Product | F1: Product Text | G1: Incentive | H1: AS-IS Qty | I1: AS-IS Amt($) | J1: TO-BE Qty | K1: TO-BE Amt($) | L1: DELTA Qty | M1: DELTA Amt($) | N1: Start Date of Condition | O1: End Date of Condition
A2: A0S3A0A250000641 | B2: VITEL W24-W26 ECO ST Promo | C2: A2S3A0A250000225 | D2: VITEL MOBILE, INC. | E2: G-WATCH-ULTRA | F2: G-WATCH-ULTRA | G2: 30 | H2: 161 | I2: 4830 | J2: 160 | K2: =J2*G2 -> 4800 | L2: =J2-H2 -> -1 | M2: =K2-I2 -> -30 | N2: 45817 | O2: 45837
A3: A0S3A0A250000641 | B3: VITEL W24-W26 ECO ST Promo | C3: A2S3A0A250000225 | D3: VITEL MOBILE, INC. | E3: SM-X520NLBATPA | F3: TABLET,SM-X520,LIGHT BLUE,TPA | G3: 30 | H3: 385 | I3: 11550 | J3: 384 | K3: =J3*G3 -> 11520 | L3: =J3-H3 -> -1 | M3: =K3-I3 -> -30 | N3: 45817 | O3: 45837
A4: A0S3A0A250000641 | B4: VITEL W24-W26 ECO ST Promo | C4: A2S3A0A250000225 | D4: VITEL MOBILE, INC. | E4: SM-X520NLBETPA | F4: TABLET,SM-X520,LIGHT BLUE,TPA | G4: 30 | H4: 3 | I4: 90 | J4: 3 | K4: =J4*G4 -> 90 | L4: =J4-H4 -> 0 | M4: =K4-I4 -> 0 | N4: 45817 | O4: 45837
A5: A0S3A0A250000641 | B5: VITEL W24-W26 ECO ST Promo | C5: A2S3A0A250000225 | D5: VITEL MOBILE, INC. | E5: SM-X520NZAATPA | F5: TABLET,SM-X520,GRAY,TPA | G5: 30 | H5: 348 | I5: 10440 | J5: 345 | K5: =J5*G5 -> 10350 | L5: =J5-H5 -> -3 | M5: =K5-I5 -> -90 | N5: 45817 | O5: 45837
A6: A0S3A0A250000641 | B6: VITEL W24-W26 ECO ST Promo | C6: A2S3A0A250000225 | D6: VITEL MOBILE, INC. | E6: SM-X520NZAETPA | F6: TABLET,SM-X520,GRAY,TPA | G6: 30 | H6: 3 | I6: 90 | J6: 3 | K6: =J6*G6 -> 90 | L6: =J6-H6 -> 0 | M6: =K6-I6 -> 0 | N6: 45817 | O6: 45837
A7: A0S3A0A250000641 | B7: VITEL W24-W26 ECO ST Promo | C7: A2S3A0A250000225 | D7: VITEL MOBILE, INC. | E7: SM-X520NZSATPA | F7: TABLET,SM-X520,SILVER,TPA | G7: 30 | H7: 347 | I7: 10410 | J7: 345 | K7: =J7*G7 -> 10350 | L7: =J7-H7 -> -2 | M7: =K7-I7 -> -60 | N7: 45817 | O7: 45837
A8: A0S3A0A250000641 | B8: VITEL W24-W26 ECO ST Promo | C8: A2S3A0A250000225 | D8: VITEL MOBILE, INC. | E8: SM-X520NZSETPA | F8: TABLET,SM-X520,SILVER,TPA | G8: 30 | H8: 3 | I8: 90 | J8: 3 | K8: =J8*G8 -> 90 | L8: =J8-H8 -> 0 | M8: =K8-I8 -> 0 | N8: 45817 | O8: 45837
A9: A0S3A0A250000641 | B9: VITEL W24-W26 ECO ST Promo | C9: A2S3A0A250000225 | D9: VITEL MOBILE, INC. | E9: SM-X526BLBATPA | F9: TABLET,SM-X526B,LIGHT BLUE,TPA | G9: 30 | H9: 135 | I9: 4050 | J9: 135 | K9: =J9*G9 -> 4050 | L9: =J9-H9 -> 0 | M9: =K9-I9 -> 0 | N9: 45817 | O9: 45837
A10: A0S3A0A250000641 | B10: VITEL W24-W26 ECO ST Promo | C10: A2S3A0A250000225 | D10: VITEL MOBILE, INC. | E10: SM-X526BZAATPA | F10: TABLET,SM-X526B,GRAY,TPA | G10: 30 | H10: 128 | I10: 3840 | J10: 128 | K10: =J10*G10 -> 3840 | L10: =J10-H10 -> 0 | M10: =K10-I10 -> 0 | N10: 45817 | O10: 45837
A11: A0S3A0A250000641 | B11: VITEL W24-W26 ECO ST Promo | C11: A2S3A0A250000225 | D11: VITEL MOBILE, INC. | E11: SM-X526BZSATPA | F11: TABLET,SM-X526B,SILVER,TPA | G11: 30 | H11: 174 | I11: 5220 | J11: 173 | K11: =J11*G11 -> 5190 | L11: =J11-H11 -> -1 | M11: =K11-I11 -> -30 | N11: 45817 | O11: 45837
A12: A0S3A0A250000641 | B12: VITEL W24-W26 ECO ST Promo | C12: A2S3A0A250000225 | D12: VITEL MOBILE, INC. | E12: SM-X620NLBATPA | F12: TABLET,SM-X620,LIGHT BLUE,TPA | G12: 30 | H12: 162 | I12: 4860 | J12: 160 | K12: =J12*G12 -> 4800 | L12: =J12-H12 -> -2 | M12: =K12-I12 -> -60 | N12: 45817 | O12: 45837
A13: A0S3A0A250000641 | B13: VITEL W24-W26 ECO ST Promo | C13: A2S3A0A250000225 | D13: VITEL MOBILE, INC. | E13: SM-X620NLBETPA | F13: TABLET,SM-X620,LIGHT BLUE,TPA | G13: 30 | H13: 3 | I13: 90 | J13: 3 | K13: =J13*G13 -> 90 | L13: =J13-H13 -> 0 | M13: =K13-I13 -> 0 | N13: 45817 | O13: 45837
... A51: A0S3A0A250000682 | B51: VITEL W26 MX Sell-Thru Promotion | C51: A2S3A0A250000242 | D51: VITEL MOBILE, INC. | E51: SM-M556BZKMTPA | F51: MOBILE,SM-M556B/DS,BLACK,TPA | G51: 7 | H51: 44 | I51: 308 | J51: 0 | K51: =J51*G51 -> 0 | L51: =J51-H51 -> -44 | M51: =K51-I51 -> -308 | N51: 45831 | O51: 45837

Sheet Invoiced old
A1: Condition Document No | B1: Condition Text | C1: Group Condition Document No | D1: Customer Text | E1: Product | F1: Product Text | G1: Incentive | H1: AS-IS Qty | I1: AS-IS Amt($) | J1: TO-BE Qty | K1: TO-BE Amt($) | L1: DELTA Qty | M1: DELTA Amt($) | N1: Start Date of Condition | O1: End Date of Condition
A2: A0S3A0A250000641 | B2: VITEL W24-W26 ECO ST Promo | C2: A2S3A0A250000225 | D2: VITEL MOBILE, INC. | E2: G-WATCH-ULTRA | F2: G-WATCH-ULTRA | G2: 30 | H2: 161 | I2: 4830 | J2: 114 | K2: =J2*G2 -> 3420 | L2: =J2-H2 -> -47 | M2: =K2-I2 -> -1410 | N2: 45817 | O2: 45837
A3: A0S3A0A250000641 | B3: VITEL W24-W26 ECO ST Promo | C3: A2S3A0A250000225 | D3: VITEL MOBILE, INC. | E3: SM-X520NLBATPA | F3: TABLET,SM-X520,LIGHT BLUE,TPA | G3: 30 | H3: 385 | I3: 11550 | J3: 153 | K3: =J3*G3 -> 4590 | L3: =J3-H3 -> -232 | M3: =K3-I3 -> -6960 | N3: 45817 | O3: 45837
A4: A0S3A0A250000641 | B4: VITEL W24-W26 ECO ST Promo | C4: A2S3A0A250000225 | D4: VITEL MOBILE, INC. | E4: SM-X520NLBETPA | F4: TABLET,SM-X520,LIGHT BLUE,TPA | G4: 30 | H4: 3 | I4: 90 | J4: 0 | K4: =J4*G4 -> 0 | L4: =J4-H4 -> -3 | M4: =K4-I4 -> -90 | N4: 45817 | O4: 45837
A5: A0S3A0A250000641 | B5: VITEL W24-W26 ECO ST Promo | C5: A2S3A0A250000225 | D5: VITEL MOBILE, INC. | E5: SM-X520NZAATPA | F5: TABLET,SM-X520,GRAY,TPA | G5: 30 | H5: 348 | I5: 10440 | J5: 240 | K5: =J5*G5 -> 7200 | L5: =J5-H5 -> -108 | M5: =K5-I5 -> -3240 | N5: 45817 | O5: 45837
A6: A0S3A0A250000641 | B6: VITEL W24-W26 ECO ST Promo | C6: A2S3A0A250000225 | D6: VITEL MOBILE, INC. | E6: SM-X520NZAETPA | F6: TABLET,SM-X520,GRAY,TPA | G6: 30 | H6: 3 | I6: 90 | J6: 0 | K6: =J6*G6 -> 0 | L6: =J6-H6 -> -3 | M6: =K6-I6 -> -90 | N6: 45817 | O6: 45837
A7: A0S3A0A250000641 | B7: VITEL W24-W26 ECO ST Promo | C7: A2S3A0A250000225 | D7: VITEL MOBILE, INC. | E7: SM-X520NZSATPA | F7: TABLET,SM-X520,SILVER,TPA | G7: 30 | H7: 347 | I7: 10410 | J7: 115 | K7: =J7*G7 -> 3450 | L7: =J7-H7 -> -232 | M7: =K7-I7 -> -6960 | N7: 45817 | O7: 45837
A8: A0S3A0A250000641 | B8: VITEL W24-W26 ECO ST Promo | C8: A2S3A0A250000225 | D8: VITEL MOBILE, INC. | E8: SM-X520NZSETPA | F8: TABLET,SM-X520,SILVER,TPA | G8: 30 | H8: 3 | I8: 90 | J8: 0 | K8: =J8*G8 -> 0 | L8: =J8-H8 -> -3 | M8: =K8-I8 -> -90 | N8: 45817 | O8: 45837
A9: A0S3A0A250000641 | B9: VITEL W24-W26 ECO ST Promo | C9: A2S3A0A250000225 | D9: VITEL MOBILE, INC. | E9: SM-X526BLBATPA | F9: TABLET,SM-X526B,LIGHT BLUE,TPA | G9: 30 | H9: 135 | I9: 4050 | J9: 25 | K9: =J9*G9 -> 750 | L9: =J9-H9 -> -110 | M9: =K9-I9 -> -3300 | N9: 45817 | O9: 45837
A10: A0S3A0A250000641 | B10: VITEL W24-W26 ECO ST Promo | C10: A2S3A0A250000225 | D10: VITEL MOBILE, INC. | E10: SM-X526BZAATPA | F10: TABLET,SM-X526B,GRAY,TPA | G10: 30 | H10: 128 | I10: 3840 | J10: 31 | K10: =J10*G10 -> 930 | L10: =J10-H10 -> -97 | M10: =K10-I10 -> -2910 | N10: 45817 | O10: 45837
A11: A0S3A0A250000641 | B11: VITEL W24-W26 ECO ST Promo | C11: A2S3A0A250000225 | D11: VITEL MOBILE, INC. | E11: SM-X526BZSATPA | F11: TABLET,SM-X526B,SILVER,TPA | G11: 30 | H11: 174 | I11: 5220 | J11: 15 | K11: =J11*G11 -> 450 | L11: =J11-H11 -> -159 | M11: =K11-I11 -> -4770 | N11: 45817 | O11: 45837
A12: A0S3A0A250000641 | B12: VITEL W24-W26 ECO ST Promo | C12: A2S3A0A250000225 | D12: VITEL MOBILE, INC. | E12: SM-X620NLBATPA | F12: TABLET,SM-X620,LIGHT BLUE,TPA | G12: 30 | H12: 162 | I12: 4860 | J12: 15 | K12: =J12*G12 -> 450 | L12: =J12-H12 -> -147 | M12: =K12-I12 -> -4410 | N12: 45817 | O12: 45837
A13: A0S3A0A250000641 | B13: VITEL W24-W26 ECO ST Promo | C13: A2S3A0A250000225 | D13: VITEL MOBILE, INC. | E13: SM-X620NLBETPA | F13: TABLET,SM-X620,LIGHT BLUE,TPA | G13: 30 | H13: 3 | I13: 90 | J13: 0 | K13: =J13*G13 -> 0 | L13: =J13-H13 -> -3 | M13: =K13-I13 -> -90 | N13: 45817 | O13: 45837
... A51: A0S3A0A250000682 | B51: VITEL W26 MX Sell-Thru Promotion | C51: A2S3A0A250000242 | D51: VITEL MOBILE, INC. | E51: SM-M556BZKMTPA | F51: MOBILE,SM-M556B/DS,BLACK,TPA | G51: 7 | H51: 44 | I51: 308 | J51: 0 | K51: =J51*G51 -> 0 | L51: =J51-H51 -> -44 | M51: =K51-I51 -> -308 | N51: 45831 | O51: 45837
